{"text": "2024-09-30 06:30:09 | INFO    | __main__:stash:131 | run - {'image': '20231121', 'version': '0.10.1.post2', 'role': 'EpicPlayer', 'headless': True}\n", "record": {"elapsed": {"repr": "0:00:01.257463", "seconds": 1.257463}, "exception": null, "extra": {"image": "20231121", "version": "0.10.1.post2", "role": "EpicPlayer", "headless": true}, "file": {"name": "claim.py", "path": "/home/runner/work/epic/epic/epic/src/claim.py"}, "function": "stash", "level": {"icon": "ℹ️", "name": "INFO", "no": 20}, "line": 131, "message": "run", "module": "claim", "name": "__main__", "process": {"id": 3655, "name": "MainProcess"}, "thread": {"id": 139968308059008, "name": "MainThread"}, "time": {"repr": "2024-09-30 06:30:09.359064+08:00", "timestamp": 1727649009.359064}}}
{"text": "2024-09-30 06:30:16 | INFO    | __main__:claim_epic_games:97 | Try to flush cookie - {'task': 'claim_epic_games'}\n", "record": {"elapsed": {"repr": "0:00:08.753669", "seconds": 8.753669}, "exception": null, "extra": {"task": "claim_epic_games"}, "file": {"name": "claim.py", "path": "/home/runner/work/epic/epic/epic/src/claim.py"}, "function": "claim_epic_games", "level": {"icon": "ℹ️", "name": "INFO", "no": 20}, "line": 97, "message": "Try to flush cookie", "module": "claim", "name": "__main__", "process": {"id": 3655, "name": "MainProcess"}, "thread": {"id": 139968308059008, "name": "MainThread"}, "time": {"repr": "2024-09-30 06:30:16.855270+08:00", "timestamp": 1727649016.85527}}}
{"text": "2024-09-30 06:30:47 | WARNING    | epic_games.agent:authorize:266 | 执行超时 - {'task': 'authorize', 'retry': 0}\n", "record": {"elapsed": {"repr": "0:00:38.956473", "seconds": 38.956473}, "exception": null, "extra": {"task": "authorize", "retry": 0}, "file": {"name": "agent.py", "path": "/home/runner/work/epic/epic/epic/src/epic_games/agent.py"}, "function": "authorize", "level": {"icon": "⚠️", "name": "WARNING", "no": 30}, "line": 266, "message": "执行超时", "module": "agent", "name": "epic_games.agent", "process": {"id": 3655, "name": "MainProcess"}, "thread": {"id": 139968308059008, "name": "MainThread"}, "time": {"repr": "2024-09-30 06:30:47.058074+08:00", "timestamp": 1727649047.058074}}}
{"text": "2024-09-30 06:30:49 | INFO    | epic_games.agent:_login:237 | login-with-email - {'url': 'https://www.epicgames.com/id/login?lang=en-US&noHostRedirect=true&redirectUrl=https://store.epicgames.com/en-US/free-games'}\n", "record": {"elapsed": {"repr": "0:00:41.510634", "seconds": 41.510634}, "exception": null, "extra": {"url": "https://www.epicgames.com/id/login?lang=en-US&noHostRedirect=true&redirectUrl=https://store.epicgames.com/en-US/free-games"}, "file": {"name": "agent.py", "path": "/home/runner/work/epic/epic/epic/src/epic_games/agent.py"}, "function": "_login", "level": {"icon": "ℹ️", "name": "INFO", "no": 20}, "line": 237, "message": "login-with-email", "module": "agent", "name": "epic_games.agent", "process": {"id": 3655, "name": "MainProcess"}, "thread": {"id": 139968308059008, "name": "MainThread"}, "time": {"repr": "2024-09-30 06:30:49.612235+08:00", "timestamp": 1727649049.612235}}}
{"text": "2024-09-30 06:30:50 | ERROR    | __main__:run:158 | An error has been caught in function 'run', process 'MainProcess' (3655), thread 'MainThread' (139968308059008): - {}\nTraceback (most recent call last):\n  File \"/home/runner/work/epic/epic/epic/src/claim.py\", line 151, in stash\n    await self.claim_epic_games(context)\n  File \"/home/runner/work/epic/epic/epic/src/claim.py\", line 98, in claim_epic_games\n    if await epic.authorize(page):\n  File \"/home/runner/work/epic/epic/epic/src/epic_games/agent.py\", line 260, in authorize\n    match await self._login(page):\n  File \"/home/runner/work/epic/epic/epic/src/epic_games/agent.py\", line 241, in _login\n    await page.click(\"//button[@aria-label='Continue']\")\n  File \"/opt/hostedtoolcache/Python/3.10.15/x64/lib/python3.10/site-packages/playwright/async_api/_generated.py\", line 9625, in click\n    await self._impl_obj.click(\n  File \"/opt/hostedtoolcache/Python/3.10.15/x64/lib/python3.10/site-packages/playwright/_impl/_page.py\", line 777, in click\n    return await self._main_frame.click(**locals_to_params(locals()))\n  File \"/opt/hostedtoolcache/Python/3.10.15/x64/lib/python3.10/site-packages/playwright/_impl/_frame.py\", line 488, in click\n    await self._channel.send(\"click\", locals_to_params(locals()))\n  File \"/opt/hostedtoolcache/Python/3.10.15/x64/lib/python3.10/site-packages/playwright/_impl/_connection.py\", line 59, in send\n    return await self._connection.wrap_api_call(\n  File \"/opt/hostedtoolcache/Python/3.10.15/x64/lib/python3.10/site-packages/playwright/_impl/_connection.py\", line 514, in wrap_api_call\n    raise rewrite_error(error, f\"{parsed_st['apiName']}: {error}\") from None\nException: Page.click: Connection closed while reading from the driver\n\nDuring handling of the above exception, another exception occurred:\n\nTraceback (most recent call last):\n  File \"/home/runner/work/epic/epic/epic/src/claim.py\", line 162, in <module>\n    asyncio.run(run())\n  File \"/opt/hostedtoolcache/Python/3.10.15/x64/lib/python3.10/asyncio/runners.py\", line 44, in run\n    return loop.run_until_complete(main)\n  File \"/opt/hostedtoolcache/Python/3.10.15/x64/lib/python3.10/asyncio/base_events.py\", line 636, in run_until_complete\n    self.run_forever()\n  File \"/opt/hostedtoolcache/Python/3.10.15/x64/lib/python3.10/asyncio/base_events.py\", line 603, in run_forever\n    self._run_once()\n  File \"/opt/hostedtoolcache/Python/3.10.15/x64/lib/python3.10/asyncio/base_events.py\", line 1909, in _run_once\n    handle._run()\n  File \"/opt/hostedtoolcache/Python/3.10.15/x64/lib/python3.10/asyncio/events.py\", line 80, in _run\n    self._context.run(self._callback, *self._args)\n> File \"/home/runner/work/epic/epic/epic/src/claim.py\", line 158, in run\n    await agent.stash()\n  File \"/home/runner/work/epic/epic/epic/src/claim.py\", line 139, in stash\n    async with async_playwright() as p:\n  File \"/opt/hostedtoolcache/Python/3.10.15/x64/lib/python3.10/site-packages/playwright/async_api/_context_manager.py\", line 57, in __aexit__\n    await self._connection.stop_async()\n  File \"/opt/hostedtoolcache/Python/3.10.15/x64/lib/python3.10/site-packages/playwright/_impl/_connection.py\", line 285, in stop_async\n    self.cleanup()\n  File \"/opt/hostedtoolcache/Python/3.10.15/x64/lib/python3.10/site-packages/playwright/_impl/_connection.py\", line 297, in cleanup\n    callback.future.set_exception(self._closed_error)\nasyncio.exceptions.InvalidStateError: invalid state\n", "record": {"elapsed": {"repr": "0:00:42.239320", "seconds": 42.23932}, "exception": {"type": "InvalidStateError", "value": "invalid state", "traceback": true}, "extra": {}, "file": {"name": "claim.py", "path": "/home/runner/work/epic/epic/epic/src/claim.py"}, "function": "run", "level": {"icon": "❌", "name": "ERROR", "no": 40}, "line": 158, "message": "An error has been caught in function 'run', process 'MainProcess' (3655), thread 'MainThread' (139968308059008):", "module": "claim", "name": "__main__", "process": {"id": 3655, "name": "MainProcess"}, "thread": {"id": 139968308059008, "name": "MainThread"}, "time": {"repr": "2024-09-30 06:30:50.340921+08:00", "timestamp": 1727649050.340921}}}
